Workbook

Sheet Painel
A1: Acompanhamento do TCC — OCR em obras literárias históricas (NUPILL/UFSC)
A2: Ewaldo Uhlmann · Orientador: Prof. Dr. Renato Fileto · Coorientador: Prof. Dr. Alckmar Luiz dos Santos
A4: Hoje | B4: =TODAY() -> 46290 | D4: Status das tarefas | E4: Qtd.
A5: Data da defesa (estimada) | B5: 46360 | D5: Concluído | E5: =COUNTIF(Tarefas!E2:E200,D5) -> 13
A6: Dias até a defesa | B6: =B5-B4 -> 70 | D6: Em andamento | E6: =COUNTIF(Tarefas!E2:E200,D6) -> 0
A7: Progresso geral (tarefas) | B7: =IF(COUNTA(Tarefas!C2:C200)=0,0,COUNTIF(Tarefas!E2:E200,"Concluído")/COUNTA(Tarefas!C2:C200)) -> 0.27659574 | D7: Pendente | E7: =COUNTIF(Tarefas!E2:E200,D7) -> 34
A8: Milestones concluídos | B8: =COUNTIF(Milestones!K2:K11,"Concluído")&" de "&COUNTA(Milestones!A2:A11) -> 1 de 10 | D8: Bloqueado | E8: =COUNTIF(Tarefas!E2:E200,D8) -> 0
A9: Tarefas atrasadas | B9: =COUNTIF(Tarefas!H2:H200,"Atrasada") -> 0
A10: Tarefas vencendo em 7 dias | B10: =COUNTIF(Tarefas!H2:H200,"Vence em 7 dias") -> 5
A12: Milestones
A13: ID | B13: Milestone | C13: % concluído | D13: Status | E13: Data alvo | F13: Situação
A14: =Milestones!A2 -> M1 | B14: =Milestones!C2 -> Revisão bibliográfica e fundamentação | C14: =Milestones!J2 -> 1 | D14: =Milestones!K2 -> Concluído | E14: =Milestones!L2 -> 46203 | F14: =Milestones!N2 -> Concluído
A15: =Milestones!A3 -> M2 | B15: =Milestones!C3 -> Regra ouro (ground truth) | C15: =Milestones!J3 -> 0.33333333 | D15: =Milestones!K3 -> Em andamento | E15: =Milestones!L3 -> 46311 | F15: =Milestones!N3 -> No prazo
A16: =Milestones!A4 -> M3 | B16: =Milestones!C4 -> Configuração dos modelos e ambiente | C16: =Milestones!J4 -> 0.5 | D16: =Milestones!K4 -> Em andamento | E16: =Milestones!L4 -> 46297 | F16: =Milestones!N4 -> Atenção
A17: =Milestones!A5 -> M4 | B17: =Milestones!C5 -> Benchmark quantitativo (CER/WER + custo) | C17: =Milestones!J5 -> 0.4 | D17: =Milestones!K5 -> Em andamento | E17: =Milestones!L5 -> 46318 | F17: =Milestones!N5 -> No prazo
A18: =Milestones!A6 -> M5 | B18: =Milestones!C6 -> Seleção do modelo | C18: =Milestones!J6 -> 0.5 | D18: =Milestones!K6 -> Em andamento | E18: =Milestones!L6 -> 46322 | F18: =Milestones!N6 -> No prazo
A19: =Milestones!A7 -> M6 | B19: =Milestones!C7 -> Pipeline de extração | C19: =Milestones!J7 -> 0.2 | D19: =Milestones!K7 -> Em andamento | E19: =Milestones!L7 -> 46318 | F19: =Milestones!N7 -> No prazo
A20: =Milestones!A8 -> M7 | B20: =Milestones!C8 -> Validação em amostra | C20: =Milestones!J8 -> 0 | D20: =Milestones!K8 -> Pendente | E20: =Milestones!L8 -> 46329 | F20: =Milestones!N8 -> No prazo
A21: =Milestones!A9 -> M8 | B21: =Milestones!C9 -> Extração completa do corpus | C21: =Milestones!J9 -> 0 | D21: =Milestones!K9 -> Pendente | E21: =Milestones!L9 -> 46339 | F21: =Milestones!N9 -> No prazo
A22: =Milestones!A10 -> M9 | B22: =Milestones!C10 -> Escrita do TCC2 | C22: =Milestones!J10 -> 0 | D22: =Milestones!K10 -> Pendente | E22: =Milestones!L10 -> 46349 | F22: =Milestones!N10 -> No prazo
A23: =Milestones!A11 -> M10 | B23: =Milestones!C11 -> Entrega e defesa | C23: =Milestones!J11 -> 0 | D23: =Milestones!K11 -> Pendente | E23: =Milestones!L11 -> 46367 | F23: =Milestones!N11 -> No prazo
A25: Como usar
A26: • Células amarelas são para editar: Status, Data alvo e Concluída em (aba Tarefas), Status (aba Capítulos) e a data da defesa (B5).
A27: • O progresso dos milestones, o status derivado e este painel são calculados por fórmula a partir da aba Tarefas — não edite essas colunas.
A28: • Para adicionar uma tarefa, preencha uma nova linha na aba Tarefas escolhendo o Milestone na lista (fórmulas cobrem até a linha 200).
A29: • Status de um milestone: Concluído se todas as tarefas estão concluídas; Bloqueado se alguma está bloqueada; Em andamento se alguma começou.
A30: • Status iniciais baseados no main.tex e no código em 25/09/2026. Datas alvo de outubro a dezembro são estimativas — ajuste ao calendário oficial.

Sheet Tarefas
A1: ID | B1: Milestone | C1: Tarefa | D1: Tipo | E1: Status | F1: Data alvo | G1: Concluída em | H1: Situação | I1: Evidência / Observações
A2: T01 | B2: M1 | C2: Escrever Cap. 2 – Fundamentação Teórica | D2: Escrita | E2: Concluído | F2: 46203 | H2: =IF(E2="Concluído","Concluída",IF(F2="","",IF(F2<TODAY(),"Atrasada",IF(F2-TODAY()<=7,"Vence em 7 dias","No prazo")))) -> Concluída | I2: main.tex
A3: T02 | B3: M1 | C3: Escrever Cap. 3 – Trabalhos Relacionados | D3: Escrita | E3: Concluído | F3: 46203 | H3: =IF(E3="Concluído","Concluída",IF(F3="","",IF(F3<TODAY(),"Atrasada",IF(F3-TODAY()<=7,"Vence em 7 dias","No prazo")))) -> Concluída | I3: main.tex
A4: T03 | B4: M1 | C4: Montar referencias.bib (ABNT) | D4: Escrita | E4: Concluído | F4: 46203 | H4: =IF(E4="Concluído","Concluída",IF(F4="","",IF(F4<TODAY(),"Atrasada",IF(F4-TODAY()<=7,"Vence em 7 dias","No prazo")))) -> Concluída | I4: escrita tcc/referencias.bib
A5: T04 | B5: M2 | C5: Selecionar obras e 20 páginas (5 fáceis, 8 médias, 7 difíceis) | D5: Dados | E5: Concluído | F5: 46203 | H5: =IF(E5="Concluído","Concluída",IF(F5="","",IF(F5<TODAY(),"Atrasada",IF(F5-TODAY()<=7,"Vence em 7 dias","No prazo")))) -> Concluída | I5: Cap. 4, Tabela de páginas
A6: T05 | B6: M2 | C6: Criar manifest.csv com obra/página/dificuldade | D6: Código | E6: Concluído | F6: 46255 | H6: =IF(E6="Concluído","Concluída",IF(F6="","",IF(F6<TODAY(),"Atrasada",IF(F6-TODAY()<=7,"Vence em 7 dias","No prazo")))) -> Concluída | I6: benchmark/ground_truth/manifest.csv
A7: T06 | B7: M2 | C7: Obter PDFs das 5 obras e salvar em data/corpus/pdfs/ | D7: Dados | E7: Pendente | F7: 46297 | H7: =IF(E7="Concluído","Concluída",IF(F7="","",IF(F7<TODAY(),"Atrasada",IF(F7-TODAY()<=7,"Vence em 7 dias","No prazo")))) -> Vence em 7 dias | I7: Pasta não existe localmente — confirmar com NUPILL
A8: T07 | B8: M2 | C8: Converter as 20 páginas da amostra em PNG (300 DPI) | D8: Dados | E8: Pendente | F8: 46297 | H8: =IF(E8="Concluído","Concluída",IF(F8="","",IF(F8<TODAY(),"Atrasada",IF(F8-TODAY()<=7,"Vence em 7 dias","No prazo")))) -> Vence em 7 dias | I8: converter.py pronto; falta executar
A9: T08 | B9: M2 | C9: Transcrever manualmente as 20 páginas (.txt) | D9: Dados | E9: Pendente | F9: 46304 | H9: =IF(E9="Concluído","Concluída",IF(F9="","",IF(F9<TODAY(),"Atrasada",IF(F9-TODAY()<=7,"Vence em 7 dias","No prazo")))) -> No prazo | I9: Cap. 4 descreve como feito, mas não há .txt no repo — marcar Concluído se já existir fora dele
A10: T09 | B10: M2 | C10: Validação das transcrições pelo Prof. Alckmar | D10: Validação | E10: Pendente | F10: 46311 | H10: =IF(E10="Concluído","Concluída",IF(F10="","",IF(F10<TODAY(),"Atrasada",IF(F10-TODAY()<=7,"Vence em 7 dias","No prazo")))) -> No prazo | I10: Divergências resolvidas por consenso (Cap. 4)
A11: T10 | B11: M3 | C11: Implementar os 13 adaptadores OCR (BaseOCR) | D11: Código | E11: Concluído | F11: 46248 | H11: =IF(E11="Concluído","Concluída",IF(F11="","",IF(F11<TODAY(),"Atrasada",IF(F11-TODAY()<=7,"Vence em 7 dias","No prazo")))) -> Concluída | I11: src/ocr/
A12: T11 | B12: M3 | C12: MODEL_REGISTRY + requirements.txt + .env.example | D12: Código | E12: Concluído | F12: 46255 | H12: =IF(E12="Concluído","Concluída",IF(F12="","",IF(F12<TODAY(),"Atrasada",IF(F12-TODAY()<=7,"Vence em 7 dias","No prazo")))) -> Concluída | I12: src/ocr/__init__.py
A13: T12 | B13: M3 | C13: Remover .env do versionamento (git rm --cached) | D13: Código | E13: Pendente | F13: 46295 | H13: =IF(E13="Concluído","Concluída",IF(F13="","",IF(F13<TODAY(),"Atrasada",IF(F13-TODAY()<=7,"Vence em 7 dias","No prazo")))) -> Vence em 7 dias | I13: .env ainda é rastreado pelo git
... A19: T18 | B19: M4 | C19: Rodar benchmark: 20 páginas × todos os modelos | D19: Experimento | E19: Pendente | F19: 46315 | H19: =IF(E19="Concluído","Concluída",IF(F19="","",IF(F19<TODAY(),"Atrasada",IF(F19-TODAY()<=7,"Vence em 7 dias","No prazo")))) -> No prazo | I19: Depende de M2 e M3
A20: T19 | B20: M4 | C20: Analisar CER/WER por classe de dificuldade | D20: Análise | E20: Pendente | F20: 46318 | H20: =IF(E20="Concluído","Concluída",IF(F20="","",IF(F20<TODAY(),"Atrasada",IF(F20-TODAY()<=7,"Vence em 7 dias","No prazo")))) -> No prazo
A21: T20 | B21: M4 | C21: Medir modernização ortográfica dos VLMs (grafias arcaicas, s longo) | D21: Análise | E21: Pendente | F21: 46318 | H21: =IF(E21="Concluído","Concluída",IF(F21="","",IF(F21<TODAY(),"Atrasada",IF(F21-TODAY()<=7,"Vence em 7 dias","No prazo")))) -> No prazo | I21: Limitação apontada por Vesalainen et al.
A22: T21 | B22: M5 | C22: Triagem por custo financeiro/computacional | D22: Escrita | E22: Concluído | F22: 46203 | H22: =IF(E22="Concluído","Concluída",IF(F22="","",IF(F22<TODAY(),"Atrasada",IF(F22-TODAY()<=7,"Vence em 7 dias","No prazo")))) -> Concluída | I22: Cap. 5, Fase 2
A23: T22 | B23: M5 | C23: Seleção preliminar do Qwen2.5-VL (baseada em literatura) | D23: Escrita | E23: Concluído | F23: 46203 | H23: =IF(E23="Concluído","Concluída",IF(F23="","",IF(F23<TODAY(),"Atrasada",IF(F23-TODAY()<=7,"Vence em 7 dias","No prazo")))) -> Concluída | I23: Cap. 5, Fase 2
A24: T23 | B24: M5 | C24: Confirmar (ou revisar) a seleção com os resultados do benchmark próprio | D24: Análise | E24: Pendente | F24: 46318 | H24: =IF(E24="Concluído","Concluída",IF(F24="","",IF(F24<TODAY(),"Atrasada",IF(F24-TODAY()<=7,"Vence em 7 dias","No prazo")))) -> No prazo | I24: Tabela atual usa CER/WER da literatura
A25: T24 | B25: M5 | C25: Atualizar tabela comparativa com CER/WER medidos | D25: Escrita | E25: Pendente | F25: 46322 | H25: =IF(E25="Concluído","Concluída",IF(F25="","",IF(F25<TODAY(),"Atrasada",IF(F25-TODAY()<=7,"Vence em 7 dias","No prazo")))) -> No prazo
A26: T25 | B26: M6 | C26: Conversão PDF → PNG (converter.py) | D26: Código | E26: Concluído | F26: 46255 | H26: =IF(E26="Concluído","Concluída",IF(F26="","",IF(F26<TODAY(),"Atrasada",IF(F26-TODAY()<=7,"Vence em 7 dias","No prazo")))) -> Concluída | I26: src/pipeline/converter.py
A27: T26 | B27: M6 | C27: Implementar run_extraction em extractor.py | D27: Código | E27: Pendente | F27: 46311 | H27: =IF(E27="Concluído","Concluída",IF(F27="","",IF(F27<TODAY(),"Atrasada",IF(F27-TODAY()<=7,"Vence em 7 dias","No prazo")))) -> No prazo | I27: Ainda é NotImplementedError
A28: T27 | B28: M6 | C28: Implementar pós-processamento (postprocessing/cleaner.py) | D28: Código | E28: Pendente | F28: 46315 | H28: =IF(E28="Concluído","Concluída",IF(F28="","",IF(F28<TODAY(),"Atrasada",IF(F28-TODAY()<=7,"Vence em 7 dias","No prazo")))) -> No prazo | I28: Arquivo citado no README, mas não existe
A29: T28 | B29: M6 | C29: Logging, tratamento de erros e retomada de execução | D29: Código | E29: Pendente | F29: 46318 | H29: =IF(E29="Concluído","Concluída",IF(F29="","",IF(F29<TODAY(),"Atrasada",IF(F29-TODAY()<=7,"Vence em 7 dias","No prazo")))) -> No prazo | I29: Necessário para as 1.043 págs. de O Feliz Independente
A30: T29 | B30: M6 | C30: Salvar resultados em data/results/{livro}/{pagina}/qwen25vl.txt | D30: Código | E30: Pendente | F30: 46318 | H30: =IF(E30="Concluído","Concluída",IF(F30="","",IF(F30<TODAY(),"Atrasada",IF(F30-TODAY()<=7,"Vence em 7 dias","No prazo")))) -> No prazo | I30: Estrutura definida no Cap. 5
A31: T30 | B31: M7 | C31: Rodar pipeline na amostra e comparar com a regra ouro | D31: Experimento | E31: Pendente | F31: 46325 | H31: =IF(E31="Concluído","Concluída",IF(F31="","",IF(F31<TODAY(),"Atrasada",IF(F31-TODAY()<=7,"Vence em 7 dias","No prazo")))) -> No prazo | I31: Fase 4
A32: T31 | B32: M7 | C32: Classificar padrões de erro sistemáticos | D32: Análise | E32: Pendente | F32: 46329 | H32: =IF(E32="Concluído","Concluída",IF(F32="","",IF(F32<TODAY(),"Atrasada",IF(F32-TODAY()<=7,"Vence em 7 dias","No prazo")))) -> No prazo
A33: T32 | B33: M7 | C33: Propor recomendações de pós-processamento | D33: Análise | E33: Pendente | F33: 46329 | H33: =IF(E33="Concluído","Concluída",IF(F33="","",IF(F33<TODAY(),"Atrasada",IF(F33-TODAY()<=7,"Vence em 7 dias","No prazo")))) -> No prazo
A34: T33 | B34: M8 | C34: Converter as 5 obras completas (1.770 págs.) | D34: Dados | E34: Pendente | F34: 46329 | H34: =IF(E34="Concluído","Concluída",IF(F34="","",IF(F34<TODAY(),"Atrasada",IF(F34-TODAY()<=7,"Vence em 7 dias","No prazo")))) -> No prazo
A35: T34 | B35: M8 | C35: Executar pipeline no corpus completo | D35: Experimento | E35: Pendente | F35: 46336 | H35: =IF(E35="Concluído","Concluída",IF(F35="","",IF(F35<TODAY(),"Atrasada",IF(F35-TODAY()<=7,"Vence em 7 dias","No prazo")))) -> No prazo | I35: Registrar tempo total e custo
A36: T35 | B36: M8 | C36: Estimar taxa de erro em larga escala | D36: Análise | E36: Pendente | F36: 46338 | H36: =IF(E36="Concluído","Concluída",IF(F36="","",IF(F36<TODAY(),"Atrasada",IF(F36-TODAY()<=7,"Vence em 7 dias","No prazo")))) -> No prazo
A37: T36 | B37: M8 | C37: Entregar textos extraídos ao NUPILL | D37: Entrega | E37: Pendente | F37: 46339 | H37: =IF(E37="Concluído","Concluída",IF(F37="","",IF(F37<TODAY(),"Atrasada",IF(F37-TODAY()<=7,"Vence em 7 dias","No prazo")))) -> No prazo
A38: T37 | B38: M9 | C38: Cap. 5: escrever Fases 4 e 5 | D38: Escrita | E38: Pendente | F38: 46332 | H38: =IF(E38="Concluído","Concluída",IF(F38="","",IF(F38<TODAY(),"Atrasada",IF(F38-TODAY()<=7,"Vence em 7 dias","No prazo")))) -> No prazo | I38: Hoje comentadas no main.tex
A39: T38 | B39: M9 | C39: Cap. 6 – Implementação e Resultados | D39: Escrita | E39: Pendente | F39: 46339 | H39: =IF(E39="Concluído","Concluída",IF(F39="","",IF(F39<TODAY(),"Atrasada",IF(F39-TODAY()<=7,"Vence em 7 dias","No prazo")))) -> No prazo
A40: T39 | B40: M9 | C40: Cap. 7 – Discussão | D40: Escrita | E40: Pendente | F40: 46343 | H40: =IF(E40="Concluído","Concluída",IF(F40="","",IF(F40<TODAY(),"Atrasada",IF(F40-TODAY()<=7,"Vence em 7 dias","No prazo")))) -> No prazo
A41: T40 | B41: M9 | C41: Cap. 8 – Conclusão (texto principal) | D41: Escrita | E41: Pendente | F41: 46345 | H41: =IF(E41="Concluído","Concluída",IF(F41="","",IF(F41<TODAY(),"Atrasada",IF(F41-TODAY()<=7,"Vence em 7 dias","No prazo")))) -> No prazo | I41: Só Trabalhos Futuros existe
A42: T41 | B42: M9 | C42: Atualizar Resumo/Abstract com os resultados | D42: Escrita | E42: Pendente | F42: 46345 | H42: =IF(E42="Concluído","Concluída",IF(F42="","",IF(F42<TODAY(),"Atrasada",IF(F42-TODAY()<=7,"Vence em 7 dias","No prazo")))) -> No prazo
A43: T42 | B43: M9 | C43: Diretrizes replicáveis + README do repositório | D43: Escrita | E43: Pendente | F43: 46345 | H43: =IF(E43="Concluído","Concluída",IF(F43="","",IF(F43<TODAY(),"Atrasada",IF(F43-TODAY()<=7,"Vence em 7 dias","No prazo")))) -> No prazo | I43: Objetivo específico 9
A44: T43 | B44: M9 | C44: Revisão do orientador (Prof. Renato Fileto) | D44: Validação | E44: Pendente | F44: 46349 | H44: =IF(E44="Concluído","Concluída",IF(F44="","",IF(F44<TODAY(),"Atrasada",IF(F44-TODAY()<=7,"Vence em 7 dias","No prazo")))) -> No prazo
A45: T44 | B45: M10 | C45: Enviar versão para a banca | D45: Entrega | E45: Pendente | F45: 46350 | H45: =IF(E45="Concluído","Concluída",IF(F45="","",IF(F45<TODAY(),"Atrasada",IF(F45-TODAY()<=7,"Vence em 7 dias","No prazo")))) -> No prazo | I45: Conferir prazo oficial do curso
...

Sheet Milestones
A1: ID | B1: Fase | C1: Milestone | D1: Obj. específicos | E1: Entregável | F1: Tarefas | G1: Concluídas | H1: Em andamento | I1: Bloqueadas | J1: % concluído | K1: Status | L1: Data alvo | M1: Dias restantes | N1: Situação
A2: M1 | B2: TCC1 | C2: Revisão bibliográfica e fundamentação | D2: 1 | E2: Caps. 2 e 3 escritos | F2: =COUNTIF(Tarefas!$B$2:$B$200,A2) -> 3 | G2: =COUNTIFS(Tarefas!$B$2:$B$200,A2,Tarefas!$E$2:$E$200,"Concluído") -> 3 | H2: =COUNTIFS(Tarefas!$B$2:$B$200,A2,Tarefas!$E$2:$E$200,"Em andamento") -> 0 | I2: =COUNTIFS(Tarefas!$B$2:$B$200,A2,Tarefas!$E$2:$E$200,"Bloqueado") -> 0 | J2: =IF(F2=0,0,G2/F2) -> 1 | K2: =IF(F2=0,"Pendente",IF(G2=F2,"Concluído",IF(I2>0,"Bloqueado",IF(G2+H2>0,"Em andamento","Pendente")))) -> Concluído | L2: =_xlfn.MAXIFS(Tarefas!$F$2:$F$200,Tarefas!$B$2:$B$200,A2) -> 46203 | M2: =IF(K2="Concluído","",L2-TODAY()) | N2: =IF(K2="Concluído","Concluído",IF(M2<0,"Atrasado",IF(M2<=7,"Atenção","No prazo"))) -> Concluído
A3: M2 | B3: TCC1/TCC2 | C3: Regra ouro (ground truth) | D3: 3 | E3: 20 .txt validados em benchmark/ground_truth/ | F3: =COUNTIF(Tarefas!$B$2:$B$200,A3) -> 6 | G3: =COUNTIFS(Tarefas!$B$2:$B$200,A3,Tarefas!$E$2:$E$200,"Concluído") -> 2 | H3: =COUNTIFS(Tarefas!$B$2:$B$200,A3,Tarefas!$E$2:$E$200,"Em andamento") -> 0 | I3: =COUNTIFS(Tarefas!$B$2:$B$200,A3,Tarefas!$E$2:$E$200,"Bloqueado") -> 0 | J3: =IF(F3=0,0,G3/F3) -> 0.33333333 | K3: =IF(F3=0,"Pendente",IF(G3=F3,"Concluído",IF(I3>0,"Bloqueado",IF(G3+H3>0,"Em andamento","Pendente")))) -> Em andamento | L3: =_xlfn.MAXIFS(Tarefas!$F$2:$F$200,Tarefas!$B$2:$B$200,A3) -> 46311 | M3: =IF(K3="Concluído","",L3-TODAY()) -> 21 | N3: =IF(K3="Concluído","Concluído",IF(M3<0,"Atrasado",IF(M3<=7,"Atenção","No prazo"))) -> No prazo
A4: M3 | B4: Fase 1 | C4: Configuração dos modelos e ambiente | D4: 2 | E4: 13 adaptadores rodando (local + API) | F4: =COUNTIF(Tarefas!$B$2:$B$200,A4) -> 6 | G4: =COUNTIFS(Tarefas!$B$2:$B$200,A4,Tarefas!$E$2:$E$200,"Concluído") -> 3 | H4: =COUNTIFS(Tarefas!$B$2:$B$200,A4,Tarefas!$E$2:$E$200,"Em andamento") -> 0 | I4: =COUNTIFS(Tarefas!$B$2:$B$200,A4,Tarefas!$E$2:$E$200,"Bloqueado") -> 0 | J4: =IF(F4=0,0,G4/F4) -> 0.5 | K4: =IF(F4=0,"Pendente",IF(G4=F4,"Concluído",IF(I4>0,"Bloqueado",IF(G4+H4>0,"Em andamento","Pendente")))) -> Em andamento | L4: =_xlfn.MAXIFS(Tarefas!$F$2:$F$200,Tarefas!$B$2:$B$200,A4) -> 46297 | M4: =IF(K4="Concluído","",L4-TODAY()) -> 7 | N4: =IF(K4="Concluído","Concluído",IF(M4<0,"Atrasado",IF(M4<=7,"Atenção","No prazo"))) -> Atenção
A5: M4 | B5: Fase 1 | C5: Benchmark quantitativo (CER/WER + custo) | D5: 2, 4 | E5: benchmark_resultados.xlsx com 20 págs × modelos | F5: =COUNTIF(Tarefas!$B$2:$B$200,A5) -> 5 | G5: =COUNTIFS(Tarefas!$B$2:$B$200,A5,Tarefas!$E$2:$E$200,"Concluído") -> 2 | H5: =COUNTIFS(Tarefas!$B$2:$B$200,A5,Tarefas!$E$2:$E$200,"Em andamento") -> 0 | I5: =COUNTIFS(Tarefas!$B$2:$B$200,A5,Tarefas!$E$2:$E$200,"Bloqueado") -> 0 | J5: =IF(F5=0,0,G5/F5) -> 0.4 | K5: =IF(F5=0,"Pendente",IF(G5=F5,"Concluído",IF(I5>0,"Bloqueado",IF(G5+H5>0,"Em andamento","Pendente")))) -> Em andamento | L5: =_xlfn.MAXIFS(Tarefas!$F$2:$F$200,Tarefas!$B$2:$B$200,A5) -> 46318 | M5: =IF(K5="Concluído","",L5-TODAY()) -> 28 | N5: =IF(K5="Concluído","Concluído",IF(M5<0,"Atrasado",IF(M5<=7,"Atenção","No prazo"))) -> No prazo
A6: M5 | B6: Fase 2 | C6: Seleção do modelo | D6: 4, 5 | E6: Seleção confirmada com métricas próprias | F6: =COUNTIF(Tarefas!$B$2:$B$200,A6) -> 4 | G6: =COUNTIFS(Tarefas!$B$2:$B$200,A6,Tarefas!$E$2:$E$200,"Concluído") -> 2 | H6: =COUNTIFS(Tarefas!$B$2:$B$200,A6,Tarefas!$E$2:$E$200,"Em andamento") -> 0 | I6: =COUNTIFS(Tarefas!$B$2:$B$200,A6,Tarefas!$E$2:$E$200,"Bloqueado") -> 0 | J6: =IF(F6=0,0,G6/F6) -> 0.5 | K6: =IF(F6=0,"Pendente",IF(G6=F6,"Concluído",IF(I6>0,"Bloqueado",IF(G6+H6>0,"Em andamento","Pendente")))) -> Em andamento | L6: =_xlfn.MAXIFS(Tarefas!$F$2:$F$200,Tarefas!$B$2:$B$200,A6) -> 46322 | M6: =IF(K6="Concluído","",L6-TODAY()) -> 32 | N6: =IF(K6="Concluído","Concluído",IF(M6<0,"Atrasado",IF(M6<=7,"Atenção","No prazo"))) -> No prazo
A7: M6 | B7: Fase 3 | C7: Pipeline de extração | D7: 6 | E7: extractor.py + cleaner.py funcionando via CLI | F7: =COUNTIF(Tarefas!$B$2:$B$200,A7) -> 5 | G7: =COUNTIFS(Tarefas!$B$2:$B$200,A7,Tarefas!$E$2:$E$200,"Concluído") -> 1 | H7: =COUNTIFS(Tarefas!$B$2:$B$200,A7,Tarefas!$E$2:$E$200,"Em andamento") -> 0 | I7: =COUNTIFS(Tarefas!$B$2:$B$200,A7,Tarefas!$E$2:$E$200,"Bloqueado") -> 0 | J7: =IF(F7=0,0,G7/F7) -> 0.2 | K7: =IF(F7=0,"Pendente",IF(G7=F7,"Concluído",IF(I7>0,"Bloqueado",IF(G7+H7>0,"Em andamento","Pendente")))) -> Em andamento | L7: =_xlfn.MAXIFS(Tarefas!$F$2:$F$200,Tarefas!$B$2:$B$200,A7) -> 46318 | M7: =IF(K7="Concluído","",L7-TODAY()) -> 28 | N7: =IF(K7="Concluído","Concluído",IF(M7<0,"Atrasado",IF(M7<=7,"Atenção","No prazo"))) -> No prazo
A8: M7 | B8: Fase 4 | C8: Validação em amostra | D8: 7, 8 | E8: Análise de erros e recomendações de pós-processamento | F8: =COUNTIF(Tarefas!$B$2:$B$200,A8) -> 3 | G8: =COUNTIFS(Tarefas!$B$2:$B$200,A8,Tarefas!$E$2:$E$200,"Concluído") -> 0 | H8: =COUNTIFS(Tarefas!$B$2:$B$200,A8,Tarefas!$E$2:$E$200,"Em andamento") -> 0 | I8: =COUNTIFS(Tarefas!$B$2:$B$200,A8,Tarefas!$E$2:$E$200,"Bloqueado") -> 0 | J8: =IF(F8=0,0,G8/F8) -> 0 | K8: =IF(F8=0,"Pendente",IF(G8=F8,"Concluído",IF(I8>0,"Bloqueado",IF(G8+H8>0,"Em andamento","Pendente")))) -> Pendente | L8: =_xlfn.MAXIFS(Tarefas!$F$2:$F$200,Tarefas!$B$2:$B$200,A8) -> 46329 | M8: =IF(K8="Concluído","",L8-TODAY()) -> 39 | N8: =IF(K8="Concluído","Concluído",IF(M8<0,"Atrasado",IF(M8<=7,"Atenção","No prazo"))) -> No prazo
A9: M8 | B9: Fase 5 | C9: Extração completa do corpus | D9: 7 | E9: Textos das 5 obras (1.770 págs.) entregues ao NUPILL | F9: =COUNTIF(Tarefas!$B$2:$B$200,A9) -> 4 | G9: =COUNTIFS(Tarefas!$B$2:$B$200,A9,Tarefas!$E$2:$E$200,"Concluído") -> 0 | H9: =COUNTIFS(Tarefas!$B$2:$B$200,A9,Tarefas!$E$2:$E$200,"Em andamento") -> 0 | I9: =COUNTIFS(Tarefas!$B$2:$B$200,A9,Tarefas!$E$2:$E$200,"Bloqueado") -> 0 | J9: =IF(F9=0,0,G9/F9) -> 0 | K9: =IF(F9=0,"Pendente",IF(G9=F9,"Concluído",IF(I9>0,"Bloqueado",IF(G9+H9>0,"Em andamento","Pendente")))) -> Pendente | L9: =_xlfn.MAXIFS(Tarefas!$F$2:$F$200,Tarefas!$B$2:$B$200,A9) -> 46339 | M9: =IF(K9="Concluído","",L9-TODAY()) -> 49 | N9: =IF(K9="Concluído","Concluído",IF(M9<0,"Atrasado",IF(M9<=7,"Atenção","No prazo"))) -> No prazo
A10: M9 | B10: Escrita | C10: Escrita do TCC2 | D10: 8, 9 | E10: Caps. 5–8 completos e revisados | F10: =COUNTIF(Tarefas!$B$2:$B$200,A10) -> 7 | G10: =COUNTIFS(Tarefas!$B$2:$B$200,A10,Tarefas!$E$2:$E$200,"Concluído") -> 0 | H10: =COUNTIFS(Tarefas!$B$2:$B$200,A10,Tarefas!$E$2:$E$200,"Em andamento") -> 0 | I10: =COUNTIFS(Tarefas!$B$2:$B$200,A10,Tarefas!$E$2:$E$200,"Bloqueado") -> 0 | J10: =IF(F10=0,0,G10/F10) -> 0 | K10: =IF(F10=0,"Pendente",IF(G10=F10,"Concluído",IF(I10>0,"Bloqueado",IF(G10+H10>0,"Em andamento","Pendente")))) -> Pendente | L10: =_xlfn.MAXIFS(Tarefas!$F$2:$F$200,Tarefas!$B$2:$B$200,A10) -> 46349 | M10: =IF(K10="Concluído","",L10-TODAY()) -> 59 | N10: =IF(K10="Concluído","Concluído",IF(M10<0,"Atrasado",IF(M10<=7,"Atenção","No prazo"))) -> No prazo
A11: M10 | B11: Entrega | C11: Entrega e defesa | D11: — | E11: Defesa realizada e versão final depositada | F11: =COUNTIF(Tarefas!$B$2:$B$200,A11) -> 4 | G11: =COUNTIFS(Tarefas!$B$2:$B$200,A11,Tarefas!$E$2:$E$200,"Concluído") -> 0 | H11: =COUNTIFS(Tarefas!$B$2:$B$200,A11,Tarefas!$E$2:$E$200,"Em andamento") -> 0 | I11: =COUNTIFS(Tarefas!$B$2:$B$200,A11,Tarefas!$E$2:$E$200,"Bloqueado") -> 0 | J11: =IF(F11=0,0,G11/F11) -> 0 | K11: =IF(F11=0,"Pendente",IF(G11=F11,"Concluído",IF(I11>0,"Bloqueado",IF(G11+H11>0,"Em andamento","Pendente")))) -> Pendente | L11: =_xlfn.MAXIFS(Tarefas!$F$2:$F$200,Tarefas!$B$2:$B$200,A11) -> 46367 | M11: =IF(K11="Concluído","",L11-TODAY()) -> 77 | N11: =IF(K11="Concluído","Concluído",IF(M11<0,"Atrasado",IF(M11<=7,"Atenção","No prazo"))) -> No prazo

Sheet Capítulos
A1: Cap. | B1: Título | C1: Etapa | D1: Status | E1: Observações
A2: 1 | B2: Introdução | C2: TCC1 | D2: Concluído | E2: Revisar 'Organização do Documento' ao final
A3: 2 | B3: Fundamentação Teórica | C3: TCC1 | D3: Concluído
A4: 3 | B4: Trabalhos Relacionados | C4: TCC1 | D4: Concluído
A5: 4 | B5: Construção da Regra Ouro | C5: TCC1 | D5: Em andamento | E5: Falta registrar resultado da validação pelo NUPILL
A6: 5 | B6: Metodologia Experimental | C6: TCC1/TCC2 | D6: Em andamento | E6: Fases 1–3 escritas; Fases 4–5 pendentes
A7: 6 | B7: Implementação e Resultados | C7: TCC2 | D7: Pendente
A8: 7 | B8: Discussão | C8: TCC2 | D8: Pendente
A9: 8 | B9: Conclusão | C9: TCC2 | D9: Em andamento | E9: Só a seção Trabalhos Futuros existe
A10: — | B10: Resumo / Abstract | C10: TCC1/TCC2 | D10: Em andamento | E10: Atualizar com resultados
